<?xml version="1.0"?>
<robot name="simple_humanoid_torso">
  <!-- Base link representing the world coordinate frame -->
  <link name="base_link"/>

  <!-- Main body/torso link -->
  <link name="torso">
    <inertial>
      <mass value="10.0"/>
      <origin xyz="0 0 0.4" rpy="0 0 0"/>
      <inertia ixx="0.8" ixy="0.0" ixz="0.0" iyy="0.8" iyz="0.0" izz="0.4"/>
    </inertial>
    <visual>
      <origin xyz="0 0 0.4" rpy="0 0 0"/>
      <geometry>
        <box size="0.3 0.4 0.8"/>
      </geometry>
      <material name="light_blue">
        <color rgba="0.6 0.8 1.0 1"/>
      </material>
    </visual>
    <collision>
      <origin xyz="0 0 0.4" rpy="0 0 0"/>
      <geometry>
        <box size="0.3 0.4 0.8"/>
      </geometry>
    </collision>
  </link>

  <!-- Joint connecting base to torso -->
  <joint name="base_to_torso" type="fixed">
    <parent link="base_link"/>
    <child link="torso"/>
    <origin xyz="0 0 0" rpy="0 0 0"/>
  </joint>

  <!-- Head link -->
  <link name="head">
    <inertial>
      <mass value="2.0"/>
      <origin xyz="0 0 0.1" rpy="0 0 0"/>
      <inertia ixx="0.02" ixy="0.0" ixz="0.0" iyy="0.02" iyz="0.0" izz="0.02"/>
    </inertial>
    <visual>
      <origin xyz="0 0 0.1" rpy="0 0 0"/>
      <geometry>
        <sphere radius="0.15"/>
      </geometry>
      <material name="skin">
        <color rgba="0.9 0.8 0.7 1"/>
      </material>
    </visual>
    <collision>
      <origin xyz="0 0 0.1" rpy="0 0 0"/>
      <geometry>
        <sphere radius="0.15"/>
      </geometry>
    </collision>
  </link>

  <!-- Neck joint -->
  <joint name="neck_joint" type="revolute">
    <parent link="torso"/>
    <child link="head"/>
    <origin xyz="0 0 0.8" rpy="0 0 0"/>
    <axis xyz="0 0 1"/>
    <limit lower="-0.5" upper="0.5" effort="10" velocity="2"/>
    <dynamics damping="0.5" friction="0.1"/>
  </joint>

  <!-- Left shoulder link -->
  <link name="left_shoulder">
    <inertial>
      <mass value="1.5"/>
      <origin xyz="0 -0.05 0" rpy="0 0 0"/>
      <inertia ixx="0.01" ixy="0.0" ixz="0.0" iyy="0.01" iyz="0.0" izz="0.01"/>
    </inertial>
    <visual>
      <origin xyz="0 -0.05 0" rpy="0 0 0"/>
      <geometry>
        <cylinder length="0.15" radius="0.06"/>
      </geometry>
      <material name="dark_gray">
        <color rgba="0.3 0.3 0.3 1"/>
      </material>
    </visual>
    <collision>
      <origin xyz="0 -0.05 0" rpy="0 0 0"/>
      <geometry>
        <cylinder length="0.15" radius="0.06"/>
      </geometry>
    </collision>
  </link>

  <!-- Left shoulder joint -->
  <joint name="left_shoulder_joint" type="revolute">
    <parent link="torso"/>
    <child link="left_shoulder"/>
    <origin xyz="0 0.225 0.5" rpy="0 0 0"/>
    <axis xyz="0 1 0"/>
    <limit lower="-1.57" upper="1.57" effort="100" velocity="2"/>
    <dynamics damping="1.0" friction="0.5"/>
  </joint>

  <!-- Left upper arm link -->
  <link name="left_upper_arm">
    <inertial>
      <mass value="1.5"/>
      <origin xyz="0 0 -0.15" rpy="0 0 0"/>
      <inertia ixx="0.02" ixy="0.0" ixz="0.0" iyy="0.02" iyz="0.0" izz="0.005"/>
    </inertial>
    <visual>
      <origin xyz="0 0 -0.15" rpy="0 0 0"/>
      <geometry>
        <cylinder length="0.3" radius="0.04"/>
      </geometry>
      <material name="light_gray">
        <color rgba="0.7 0.7 0.7 1"/>
      </material>
    </visual>
    <collision>
      <origin xyz="0 0 -0.15" rpy="0 0 0"/>
      <geometry>
        <cylinder length="0.3" radius="0.04"/>
      </geometry>
    </collision>
  </link>

  <!-- Left elbow joint -->
  <joint name="left_elbow_joint" type="revolute">
    <parent link="left_shoulder"/>
    <child link="left_upper_arm"/>
    <origin xyz="0 -0.1 0" rpy="0 0 0"/>
    <axis xyz="0 1 0"/>
    <limit lower="-2.36" upper="2.36" effort="100" velocity="1.5"/>
    <dynamics damping="0.8" friction="0.3"/>
  </joint>

  <!-- Left forearm link -->
  <link name="left_forearm">
    <inertial>
      <mass value="1.0"/>
      <origin xyz="0 0 -0.12" rpy="0 0 0"/>
      <inertia ixx="0.01" ixy="0.0" ixz="0.0" iyy="0.01" iyz="0.0" izz="0.003"/>
    </inertial>
    <visual>
      <origin xyz="0 0 -0.12" rpy="0 0 0"/>
      <geometry>
        <cylinder length="0.24" radius="0.035"/>
      </geometry>
      <material name="medium_gray">
        <color rgba="0.5 0.5 0.5 1"/>
      </material>
    </visual>
    <collision>
      <origin xyz="0 0 -0.12" rpy="0 0 0"/>
      <geometry>
        <cylinder length="0.24" radius="0.035"/>
      </geometry>
    </collision>
  </link>

  <!-- Left wrist joint -->
  <joint name="left_wrist_joint" type="revolute">
    <parent link="left_upper_arm"/>
    <child link="left_forearm"/>
    <origin xyz="0 0 -0.3" rpy="0 0 0"/>
    <axis xyz="1 0 0"/>
    <limit lower="-1.57" upper="1.57" effort="50" velocity="2.5"/>
    <dynamics damping="0.5" friction="0.2"/>
  </joint>

  <!-- Right shoulder link -->
  <link name="right_shoulder">
    <inertial>
      <mass value="1.5"/>
      <origin xyz="0 0.05 0" rpy="0 0 0"/>
      <inertia ixx="0.01" ixy="0.0" ixz="0.0" iyy="0.01" iyz="0.0" izz="0.01"/>
    </inertial>
    <visual>
      <origin xyz="0 0.05 0" rpy="0 0 0"/>
      <geometry>
        <cylinder length="0.15" radius="0.06"/>
      </geometry>
      <material name="dark_gray">
        <color rgba="0.3 0.3 0.3 1"/>
      </material>
    </visual>
    <collision>
      <origin xyz="0 0.05 0" rpy="0 0 0"/>
      <geometry>
        <cylinder length="0.15" radius="0.06"/>
      </geometry>
    </collision>
  </link>

  <!-- Right shoulder joint -->
  <joint name="right_shoulder_joint" type="revolute">
    <parent link="torso"/>
    <child link="right_shoulder"/>
    <origin xyz="0 -0.225 0.5" rpy="0 0 0"/>
    <axis xyz="0 1 0"/>
    <limit lower="-1.57" upper="1.57" effort="100" velocity="2"/>
    <dynamics damping="1.0" friction="0.5"/>
  </joint>

  <!-- Right upper arm link -->
  <link name="right_upper_arm">
    <inertial>
      <mass value="1.5"/>
      <origin xyz="0 0 -0.15" rpy="0 0 0"/>
      <inertia ixx="0.02" ixy="0.0" ixz="0.0" iyy="0.02" iyz="0.0" izz="0.005"/>
    </inertial>
    <visual>
      <origin xyz="0 0 -0.15" rpy="0 0 0"/>
      <geometry>
        <cylinder length="0.3" radius="0.04"/>
      </geometry>
      <material name="light_gray">
        <color rgba="0.7 0.7 0.7 1"/>
      </material>
    </visual>
    <collision>
      <origin xyz="0 0 -0.15" rpy="0 0 0"/>
      <geometry>
        <cylinder length="0.3" radius="0.04"/>
      </geometry>
    </collision>
  </link>

  <!-- Right elbow joint -->
  <joint name="right_elbow_joint" type="revolute">
    <parent link="right_shoulder"/>
    <child link="right_upper_arm"/>
    <origin xyz="0 0.1 0" rpy="0 0 0"/>
    <axis xyz="0 1 0"/>
    <limit lower="-2.36" upper="2.36" effort="100" velocity="1.5"/>
    <dynamics damping="0.8" friction="0.3"/>
  </joint>

  <!-- Right forearm link -->
  <link name="right_forearm">
    <inertial>
      <mass value="1.0"/>
      <origin xyz="0 0 -0.12" rpy="0 0 0"/>
      <inertia ixx="0.01" ixy="0.0" ixz="0.0" iyy="0.01" iyz="0.0" izz="0.003"/>
    </inertial>
    <visual>
      <origin xyz="0 0 -0.12" rpy="0 0 0"/>
      <geometry>
        <cylinder length="0.24" radius="0.035"/>
      </geometry>
      <material name="medium_gray">
        <color rgba="0.5 0.5 0.5 1"/>
      </material>
    </visual>
    <collision>
      <origin xyz="0 0 -0.12" rpy="0 0 0"/>
      <geometry>
        <cylinder length="0.24" radius="0.035"/>
      </geometry>
    </collision>
  </link>

  <!-- Right wrist joint -->
  <joint name="right_wrist_joint" type="revolute">
    <parent link="right_upper_arm"/>
    <child link="right_forearm"/>
    <origin xyz="0 0 -0.3" rpy="0 0 0"/>
    <axis xyz="1 0 0"/>
    <limit lower="-1.57" upper="1.57" effort="50" velocity="2.5"/>
    <dynamics damping="0.5" friction="0.2"/>
  </joint>

  <!-- Gazebo-specific properties for simulation -->
  <gazebo reference="torso">
    <material>Gazebo/Blue</material>
    <mu1>0.2</mu1>
    <mu2>0.2</mu2>
    <kp>1000000.0</kp>
    <kd>1.0</kd>
  </gazebo>

  <gazebo reference="head">
    <material>Gazebo/Yellow</material>
    <mu1>0.2</mu1>
    <mu2>0.2</mu2>
    <kp>1000000.0</kp>
    <kd>1.0</kd>
  </gazebo>

  <gazebo reference="left_shoulder">
    <material>Gazebo/Black</material>
    <mu1>0.2</mu1>
    <mu2>0.2</mu2>
    <kp>1000000.0</kp>
    <kd>1.0</kd>
  </gazebo>

  <gazebo reference="left_upper_arm">
    <material>Gazebo/Gray</material>
    <mu1>0.2</mu1>
    <mu2>0.2</mu2>
    <kp>1000000.0</kp>
    <kd>1.0</kd>
  </gazebo>

  <gazebo reference="left_forearm">
    <material>Gazebo/Gray</material>
    <mu1>0.2</mu1>
    <mu2>0.2</mu2>
    <kp>1000000.0</kp>
    <kd>1.0</kd>
  </gazebo>

  <gazebo reference="right_shoulder">
    <material>Gazebo/Black</material>
    <mu1>0.2</mu1>
    <mu2>0.2</mu2>
    <kp>1000000.0</kp>
    <kd>1.0</kd>
  </gazebo>

  <gazebo reference="right_upper_arm">
    <material>Gazebo/Gray</material>
    <mu1>0.2</mu1>
    <mu2>0.2</mu2>
    <kp>1000000.0</kp>
    <kd>1.0</kd>
  </gazebo>

  <gazebo reference="right_forearm">
    <material>Gazebo/Gray</material>
    <mu1>0.2</mu1>
    <mu2>0.2</mu2>
    <kp>1000000.0</kp>
    <kd>1.0</kd>
  </gazebo>

  <!-- Transmission elements for ROS control -->
  <transmission name="left_shoulder_trans">
    <type>transmission_interface/SimpleTransmission</type>
    <joint name="left_shoulder_joint">
      <hardwareInterface>hardware_interface/EffortJointInterface</hardwareInterface>
    </joint>
    <actuator name="left_shoulder_motor">
      <hardwareInterface>hardware_interface/EffortJointInterface</hardwareInterface>
      <mechanicalReduction>1</mechanicalReduction>
    </actuator>
  </transmission>

  <transmission name="left_elbow_trans">
    <type>transmission_interface/SimpleTransmission</type>
    <joint name="left_elbow_joint">
      <hardwareInterface>hardware_interface/EffortJointInterface</hardwareInterface>
    </joint>
    <actuator name="left_elbow_motor">
      <hardwareInterface>hardware_interface/EffortJointInterface</hardwareInterface>
      <mechanicalReduction>1</mechanicalReduction>
    </actuator>
  </transmission>

  <transmission name="left_wrist_trans">
    <type>transmission_interface/SimpleTransmission</type>
    <joint name="left_wrist_joint">
      <hardwareInterface>hardware_interface/EffortJointInterface</hardwareInterface>
    </joint>
    <actuator name="left_wrist_motor">
      <hardwareInterface>hardware_interface/EffortJointInterface</hardwareInterface>
      <mechanicalReduction>1</mechanicalReduction>
    </actuator>
  </transmission>

  <transmission name="right_shoulder_trans">
    <type>transmission_interface/SimpleTransmission</type>
    <joint name="right_shoulder_joint">
      <hardwareInterface>hardware_interface/EffortJointInterface</hardwareInterface>
    </joint>
    <actuator name="right_shoulder_motor">
      <hardwareInterface>hardware_interface/EffortJointInterface</hardwareInterface>
      <mechanicalReduction>1</mechanicalReduction>
    </actuator>
  </transmission>

  <transmission name="right_elbow_trans">
    <type>transmission_interface/SimpleTransmission</type>
    <joint name="right_elbow_joint">
      <hardwareInterface>hardware_interface/EffortJointInterface</hardwareInterface>
    </joint>
    <actuator name="right_elbow_motor">
      <hardwareInterface>hardware_interface/EffortJointInterface</hardwareInterface>
      <mechanicalReduction>1</mechanicalReduction>
    </actuator>
  </transmission>

  <transmission name="right_wrist_trans">
    <type>transmission_interface/SimpleTransmission</type>
    <joint name="right_wrist_joint">
      <hardwareInterface>hardware_interface/EffortJointInterface</hardwareInterface>
    </joint>
    <actuator name="right_wrist_motor">
      <hardwareInterface>hardware_interface/EffortJointInterface</hardwareInterface>
      <mechanicalReduction>1</mechanicalReduction>
    </actuator>
  </transmission>

  <transmission name="neck_trans">
    <type>transmission_interface/SimpleTransmission</type>
    <joint name="neck_joint">
      <hardwareInterface>hardware_interface/EffortJointInterface</hardwareInterface>
    </joint>
    <actuator name="neck_motor">
      <hardwareInterface>hardware_interface/EffortJointInterface</hardwareInterface>
      <mechanicalReduction>1</mechanicalReduction>
    </actuator>
  </transmission>
</robot>