<?xml version="1.0"?>
<robot name="simple_humanoid_arm">
  <!-- Base/shoulder link -->
  <link name="shoulder_link">
    <inertial>
      <mass value="2.0"/>
      <origin xyz="0 0 0.1" rpy="0 0 0"/>
      <inertia ixx="0.01" ixy="0.0" ixz="0.0" iyy="0.01" iyz="0.0" izz="0.01"/>
    </inertial>
    <visual>
      <origin xyz="0 0 0.1" rpy="0 0 0"/>
      <geometry>
        <cylinder length="0.2" radius="0.05"/>
      </geometry>
      <material name="blue">
        <color rgba="0 0 1 1"/>
      </material>
    </visual>
    <collision>
      <origin xyz="0 0 0.1" rpy="0 0 0"/>
      <geometry>
        <cylinder length="0.2" radius="0.05"/>
      </geometry>
    </collision>
  </link>

  <!-- Shoulder joint -->
  <joint name="shoulder_joint" type="revolute">
    <parent link="shoulder_link"/>
    <child link="upper_arm_link"/>
    <origin xyz="0 0 0.2" rpy="0 0 0"/>
    <axis xyz="0 1 0"/>
    <limit lower="-1.57" upper="1.57" effort="100" velocity="1"/>
    <dynamics damping="0.1" friction="0.0"/>
  </joint>

  <!-- Upper arm link -->
  <link name="upper_arm_link">
    <inertial>
      <mass value="1.5"/>
      <origin xyz="0 0 0.15" rpy="0 0 0"/>
      <inertia ixx="0.02" ixy="0.0" ixz="0.0" iyy="0.02" iyz="0.0" izz="0.005"/>
    </inertial>
    <visual>
      <origin xyz="0 0 0.15" rpy="0 0 0"/>
      <geometry>
        <cylinder length="0.3" radius="0.04"/>
      </geometry>
      <material name="red">
        <color rgba="1 0 0 1"/>
      </material>
    </visual>
    <collision>
      <origin xyz="0 0 0.15" rpy="0 0 0"/>
      <geometry>
        <cylinder length="0.3" radius="0.04"/>
      </geometry>
    </collision>
  </link>

  <!-- Elbow joint -->
  <joint name="elbow_joint" type="revolute">
    <parent link="upper_arm_link"/>
    <child link="forearm_link"/>
    <origin xyz="0 0 0.3" rpy="0 0 0"/>
    <axis xyz="0 1 0"/>
    <limit lower="-2.36" upper="2.36" effort="100" velocity="1"/>
    <dynamics damping="0.1" friction="0.0"/>
  </joint>

  <!-- Forearm link -->
  <link name="forearm_link">
    <inertial>
      <mass value="1.0"/>
      <origin xyz="0 0 0.12" rpy="0 0 0"/>
      <inertia ixx="0.01" ixy="0.0" ixz="0.0" iyy="0.01" iyz="0.0" izz="0.003"/>
    </inertial>
    <visual>
      <origin xyz="0 0 0.12" rpy="0 0 0"/>
      <geometry>
        <cylinder length="0.24" radius="0.035"/>
      </geometry>
      <material name="green">
        <color rgba="0 1 0 1"/>
      </material>
    </visual>
    <collision>
      <origin xyz="0 0 0.12" rpy="0 0 0"/>
      <geometry>
        <cylinder length="0.24" radius="0.035"/>
      </geometry>
    </collision>
  </link>

  <!-- End effector joint (fixed connection) -->
  <joint name="wrist_joint" type="fixed">
    <parent link="forearm_link"/>
    <child link="end_effector"/>
    <origin xyz="0 0 0.24" rpy="0 0 0"/>
  </joint>

  <!-- End effector link -->
  <link name="end_effector">
    <inertial>
      <mass value="0.1"/>
      <origin xyz="0 0 0.02" rpy="0 0 0"/>
      <inertia ixx="0.0001" ixy="0.0" ixz="0.0" iyy="0.0001" iyz="0.0" izz="0.0001"/>
    </inertial>
    <visual>
      <origin xyz="0 0 0.02" rpy="0 0 0"/>
      <geometry>
        <sphere radius="0.02"/>
      </geometry>
      <material name="yellow">
        <color rgba="1 1 0 1"/>
      </material>
    </visual>
    <collision>
      <origin xyz="0 0 0.02" rpy="0 0 0"/>
      <geometry>
        <sphere radius="0.02"/>
      </geometry>
    </collision>
  </link>

  <!-- Define the base of the robot that connects to the rest of the humanoid -->
  <joint name="base_fixed_joint" type="fixed">
    <parent link="world"/>
    <child link="shoulder_link"/>
    <origin xyz="0 0 1.0" rpy="0 0 0"/>
  </joint>

  <!-- Virtual world link for connection reference -->
  <link name="world"/>
</robot>